Workbook

Sheet Маршрут
B2: ="До поїдки залишилось: " & INT(B5-NOW()) & " дн. " & HOUR(B5-NOW()) & "г " & TEXT(MINUTE(B5-NOW()), "00") & "хв" -> До поїдки залишилось: 61 дн. 1г 05хв
B5: 46214.375
A6: 📍 Camino Português da Costa | E6: Альберге | I6: Что посмотреть | L6: Печать
A7: Дата | B7: Этап | C7: Км офиц. | D7: Описание | E7: Альберге | F7: €/чел | G7: Альберге | H7: €/чел | I7: Что посмотреть | K7: Что посмотреть | L7: Место | M7: Почему интересна | N7: Место | O7: Почему интересна
A8: 11.07 | B8: Portu — день прилета | D8: Привет Океан | E8: Best Guest Porto Hostel | F8: 25 | G8: Albergue de Peregrinos Porto | H8: 15 | I8: Livraria Lello | J8: Foz do Douro | K8: Ponte Luís I | L8: Кафедральный собор Порту | M8: Выдают Credential (2€) + первая печать. ОБЯЗАТЕЛЬНО
A9: 12.07 | B9: День в Порту (свободный) | D9: Весь день по набережной и пляжам | E9: Best Guest Porto Hostel | F9: 25 | I9: Matosinhos | J9: Jardins do Palácio de Cristal | K9: Mercado do Bolhão
A10: 13.07 | B10: Portu → Vila do Conde | C10: 28 | D10: Весь день по набережной и пляжам Matosinhos. | E10: Albergue de Peregrinos do Mosteiro de Vairão | F10: 15 | G10: Albergue de Peregrinos São José de Ribamar | H10: 15 | I10: Igreja e Mosteiro de Santa Clara | L10: Nau Quinhentista | M10: Уникальная морская печать символ эпохи Великих открытий | N10: Mosteiro de Santa Clara | O10: Монастырь XIV века - редкая готическая печать
A11: 14.07 | B11: Vila do Conde → Esposende | C11: 23 | D11: Boardwalk вдоль пляжей, частично по берегу | E11: Albergue de Peregrinos de Marinhas | F11: 15 | I11: Igreja Matriz de Esposende | J11: Aqueduto de Santa Clara | M11: Маленькие города дают самые колоритные печати
A12: 15.07 | B12: Esposende → Viana do Castelo | C12: 25 | D12: Маршрут уходит внутрь страны | E12: Albergue S. João dos Caminhos (церковь) | F12: 15 | G12: Albergue de Santa Luzia | H12: 20 | I12: Monte Sta Luzia | L12: Santuário do Sagrado Coração de Jesus | M12: Вид на город и океан — одна из красивейших остановок | N12: Câmara Municipal (мэрия) | O12: Официальная печать с гербом города
A13: 16.07 | B13: Viana do Castelo → Caminha | C13: 27 | D13: Короткие выходы у Vila Praia de Âncora | E13: Albergue Municipal Caminha (у океана) | F13: 15 | G13: Public Pilgrims Hostel of A Guarda | H13: 10 | I13: ПАРОМ В ИСПАНИЮ отсюда! | J13: Santuário de Santa Luzia | K13: Chafariz de Caminha | L13: Caminha Main Church | M13: XV век — прямо у площади с фонтаном | N13: Паромная компания | O13: Паром через Миньо - попросите печать! Редкость
A14: 17.07 | B14: Caminha → A Guarda → Baiona | C14: 32 | D14: паром устье реки Миньо. Галисии красивый участок маршрута! | E14: чистенько 15 евро | F14: 15 | G14: на берегу - 18 евро | H14: 18 | I14: Castro de Santa Tegra | J14: Fortaleza de Monterreal | K14: Réplica da Carabela La Pinta | L14: Castro de Santa Tegra | M14: Кельтское городище II в. до н.э. экзотическая печать
I15: пляж Praia América | L15: Fortaleza de Monterreal | M15: Здесь узнали о Новом Свете | N15: Réplica da Carabela A Pinta | O15: Копия корабля Колумба. Такой печати нет нигде в мире
A16: 18.07 | B16: Baiona → Vigo | C16: 26 | D16: Маршрут уходит внутрь страны | E16: далеко от центра 10 евро | F16: 15 | G16: в центре 15 евро | H16: 15 | I16: Basílica de Santa María la Mayor | M16: Начало последних 100 км — важная отметка для Compostela
A17: 19.07 | B17: Vigo → Redondela | C17: 16 | D17: Леса, деревни | E17: Albergue de peregrinos Casa da Torre | F17: 15 | I17: Viaduto de Pontevedra | K17: Alameda Castelao | L17: Igrexa de Santiago de Redondela | M17: Слияние Прибрежного и Центрального маршрутов
A18: 20.07 | B18: Redondela → Pontevedra | C18: 20 | D18: Леса, деревни, | E18: ACOLÁ hostel | F18: 15 | G18: Хочу сюда | H18: 15 | I18: Ponte do Burgo | J18: Plaza da Leña | K18: Ottone Pontevedra | L18: Iglesia de Santa María la Mayor | M18: Красивейшая готика Галисии
A19: 21.07 | B19: Pontevedra → Caldas de Reis | C19: 21 | D19: Леса, деревни | E19: Albergue Público de Peregrinos de Caldas de Reis | F19: 15 | I19: Iglesia de Santo Tomás Becket | L19: Fonte das Burgas | M19: Попросите печать в алберге у источника
A20: 22.07 | B20: Caldas → Padrón | C20: 19 | D20: Леса, деревни, | E20: Albergue Municipal Padrón | F20: 15 | I20: Iglesia de Santiago de Padrón | J20: Santiaguiño do Monte - маленьке місце паломників, мало хто знає. | M20: Здесь по легенде прибыли мощи св.Якова. Одна из главных!
A21: 23.07 | B21: Padrón → Santiago | C21: 24 | D21: Леса, деревни | E21: Красивый возле собора 24 евро | F21: 15 | G21: огромный 10 евро | H21: 10 | I21: Catedral de Santiago de Compostela | J21: Parque da Alameda | K21: Mercado de Abastos | L21: Pilgrim's Reception Office | M21: Апостол Сантьяго последняя печать перед Compostela
A22: 24.07 | B22: Автобус→Fisterra + Возврат Fisterra→Santiago | D22: Конец света! | E22: Красивый возле собора 24 евро | F22: 15 | G22: огромный 10 евро | H22: 10 | I22: Faro de Fisterra | J22: захід сонця на маяку - одна з головних причин туди їхати. | L22: Faro de Fisterra (маяк) | M22: Самая западная точка. Уникальный штемпель маяка
A23: 25.07 | B23: Santiago→Порту→Бухарест
A24: Всего | C24: =C10+C11+C12+C13+C14+C15+C16+C17+C18+C19+C20+C21 -> 261

Sheet Things
B1: ='Маршрут'!A6 -> 📍 Camino Português da Costa
C3: Микола | D3: Олекса | E3: Ганна | F3: Євген | H3: Комментарі
B4: Квитки | C4: TRUE | D4: TRUE | E4: FALSE | F4: TRUE
B5: Рюкзак | C5: FALSE | D5: TRUE | E5: TRUE | F5: TRUE | H5: Pinguin Fly 35 | J5: Osprey Exos 34 | L5: Forclaz40AIR | N5: Osprey Hikelite 28 | P5: Osprey Sirrus 36 | R5: Osprey Tempest 33 | T5: Osprey Talon 33 | V5: Deuter Trail 30 | X5: https://leobox.ua/riukzak-pentagram-30-l-karkasna-spynka-dlia-turyzmu-velosportu-ta-mista-biriuzovyi-peacock-blue/
B6: Кросівки для трейлранінгу | C6: TRUE | D6: TRUE | E6: FALSE | F6: TRUE | H6: Evadict MT Cushion 2 | Quechua FH500 fast hiking | Evadict Race Light(для Саші) | Hoka Speedgoat 5 |Hoka Challenger 7 | Hoka Anacapa Breeze Low | Salomon ultra glide 2
B7: Дождевик-пончо | C7: FALSE | D7: FALSE | E7: FALSE | F7: TRUE | H7: https://www.decathlon.ro/toate-sporturile/drumetie-trekking/poncho-si-huse-impermeabile
B8: Трекінгові палиці | C8: FALSE | D8: FALSE | E8: FALSE | F8: FALSE | H8: КУПИМО В ПОРТО | J8: хлопчики - Forclaz MT500 Hiking Pole | N8: жіночка - Forclaz MT100 Comfort | R8: дівчинка - Forclaz MT100 Junior
B9: Linen у Спальный мішок | C9: FALSE | D9: FALSE | E9: FALSE | F9: TRUE
B10: Шлепанцы | C10: FALSE | D10: FALSE | E10: FALSE | F10: TRUE
B11: Футболка 2шт (Синтетика чи Мерінос) | C11: FALSE | D11: FALSE | E11: FALSE | F11: TRUE | H11: Quechua MH100 | J11: https://www.decathlon.ro/p/camasa-cu-maneca-scurta-pentru-drumetie-nh100-bej-barbati/_/R-p-337820?mc=8969134&c=BEJ
B12: Сорочка UPF | C12: FALSE | D12: FALSE | E12: FALSE | F12: FALSE | H12: https://www.decathlon.ro/p/camasa-cu-maneci-lungi-anti-uv-travel-900-stretch-gri-barbati/_/R-p-349746?mc=8826045&c=GRI
B13: Фліска | C13: FALSE | D13: FALSE | E13: FALSE | F13: FALSE
B14: Шорти | C14: FALSE | D14: FALSE | E14: FALSE | F14: TRUE
B15: Спортивки | C15: FALSE | D15: FALSE | E15: FALSE | F15: FALSE
B16: Нижнее белье 2 пари | C16: FALSE | D16: FALSE | E16: FALSE | F16: TRUE
B17: Шкарпетки (wrightstock)(мерінос) | C17: FALSE | D17: FALSE | E17: FALSE | F17: TRUE | H17: Forclaz MT900 anti-blister | Forclaz MT500 Fresh | Darn ToughLight hiker MicroCrew | Smartwool PhD Outdoor Light
B18: Свитшот/вітровка/фліска | C18: FALSE | D18: FALSE | E18: FALSE | F18: TRUE
B19: Окуляри (захист рівень 3) | C19: TRUE | D19: TRUE | E19: FALSE | F19: TRUE
B20: Кепка / Панамка | C20: TRUE | D20: TRUE | E20: FALSE | F20: TRUE
B21: Бананка | C21: FALSE | D21: FALSE | E21: FALSE | F21: TRUE
B22: Шопер | C22: FALSE | D22: FALSE | E22: FALSE | F22: TRUE
B23: Баф | C23: FALSE | D23: FALSE | E23: FALSE | F23: TRUE
B24: Купальники | C24: FALSE | D24: FALSE | E24: FALSE | F24: TRUE
B25: рушник мікрофібра | C25: FALSE | D25: FALSE | E25: FALSE | F25: TRUE
B26: Щітка зубна, паста | C26: FALSE | D26: FALSE | E26: FALSE | F26: TRUE
B27: Шампунь | C27: FALSE | D27: FALSE | E27: FALSE | F27: TRUE
B28: Туалетная бумага | C28: FALSE | D28: FALSE | E28: FALSE | F28: TRUE
B29: Салфетки | C29: FALSE | D29: FALSE | E29: FALSE | F29: TRUE
B30: Бутылки для воды. Пластік 1л | C30: FALSE | D30: FALSE | E30: FALSE | F30: FALSE | H30: https://www.decathlon.ro/p/mp/safe4sport/soft-flask-sticla-de-apa-flexibila-pentru-alergare-500-ml/_/R-p-247fd876-63e0-4225-bc1c-98a2430442bc
B31: Кружка, миска, ложки???? | C31: FALSE | D31: FALSE | E31: FALSE | F31: TRUE | H31: Чи треба?
B32: Солнцезащитный крем SPF50 | C32: FALSE | D32: FALSE | E32: FALSE | F32: TRUE
B33: Антифрикційний крем, стік, від натирання | C33: TRUE | D33: TRUE | E33: FALSE | F33: TRUE
B34: пластирь Compeed чи Urgo | C34: FALSE | D34: FALSE | E34: FALSE | F34: FALSE | H34: https://www.decathlon.pt/p/mp/compeed-ampollas-extreme-5-ud/1db22bb1-cb4e-4c23-99a0-9b38e4114f4e/novar
B35: аптечка (пластыри, антисептик, обезболивающие, противовоспалительные средства, желудочные, вазелін) | C35: FALSE | D35: FALSE | E35: FALSE | F35: FALSE
B36: електроліти | C36: FALSE | D36: FALSE | E36: FALSE | F36: FALSE
B37: документы | C37: FALSE | D37: FALSE | E37: FALSE | F37: FALSE
B38: картки | C38: FALSE | D38: FALSE | E38: FALSE | F38: FALSE
B39: готівка | C39: FALSE | D39: FALSE | E39: FALSE | F39: FALSE
B40: Ліхтарик | C40: FALSE | D40: FALSE | E40: FALSE | F40: TRUE
B41: Мобильный телефон | C41: FALSE | D41: FALSE | E41: FALSE | F41: FALSE
...

Sheet Budget 
J1: ="До поїдки залишилось: " & INT(J4-NOW()) & " дн. " & HOUR(J4-NOW()) & "г " & TEXT(MINUTE(J4-NOW()), "00") & "хв" -> До поїдки залишилось: 61 дн. 1г 05хв
N2: EURO | O2: 5.1
J4: 46214.375
A5: День | B5: Категория | C5: cost | D5: times | E5: Plan (€)
A6: ='Маршрут'!A8 -> 11.07 | B6: ='Маршрут'!B8 -> Portu — день прилета | C6: 369 | D6: 2 | E6: =C6*D6/O2 -> 144.70588
B7: Метро Аэропорт → гостиница | D7: 2 | E7: =D7*C7 -> 0
B8: ночквка в Portu | D8: 2 | E8: =C8*D8 -> 0
A9: ='Маршрут'!A9 -> 12.07 | B9: ='Маршрут'!B9 -> День в Порту (свободный) | D9: 2 | E9: =C9*D9 -> 0
A10: ='Маршрут'!A10 -> 13.07 | B10: ='Маршрут'!B10 -> Portu → Vila do Conde | D10: 2 | E10: =C10*D10 -> 0
A11: ='Маршрут'!A11 -> 14.07 | B11: ='Маршрут'!B11 -> Vila do Conde → Esposende | D11: 2 | E11: =C11*D11 -> 0
A12: ='Маршрут'!A12 -> 15.07 | B12: ='Маршрут'!B12 -> Esposende → Viana do Castelo | D12: 2 | E12: =C12*D12 -> 0
A13: ='Маршрут'!A13 -> 16.07 | B13: ='Маршрут'!B13 -> Viana do Castelo → Caminha | D13: 2 | E13: =C13*D13 -> 0
A14: ='Маршрут'!A14 -> 17.07 | B14: ='Маршрут'!B14 -> Caminha → A Guarda → Baiona | D14: 2 | E14: =C14*D14 -> 0
A15: ='Маршрут'!A16 -> 18.07 | B15: ='Маршрут'!B16 -> Baiona → Vigo | D15: 2 | E15: =C15*D15 -> 0
A16: ='Маршрут'!A17 -> 19.07 | B16: ='Маршрут'!B17 -> Vigo → Redondela | D16: 2 | E16: =C16*D16 -> 0
A17: ='Маршрут'!A18 -> 20.07 | B17: ='Маршрут'!B18 -> Redondela → Pontevedra | D17: 2 | E17: =C17*D17 -> 0
A18: ='Маршрут'!A19 -> 21.07 | B18: ='Маршрут'!B19 -> Pontevedra → Caldas de Reis | D18: 2 | E18: =C18*D18 -> 0
A19: ='Маршрут'!A20 -> 22.07 | B19: ='Маршрут'!B20 -> Caldas → Padrón | D19: 2 | E19: =C19*D19 -> 0
A20: ='Маршрут'!A21 -> 23.07 | B20: ='Маршрут'!B21 -> Padrón → Santiago | D20: 2 | E20: =D20*C20 -> 0
A21: ='Маршрут'!A22 -> 24.07 | B21: День в Fisterra | D21: 2 | E21: =C21*D21 -> 0
A22: ='Маршрут'!A23 -> 25.07 | B22: Автобус Fisterra → Santiago | D22: 2 | E22: =D22*C22 -> 0
B23: Дорогоа в Порту | D23: 2 | E23: =D23*C23 -> 0
B24: Самолёт Порту → Бухарест | C24: 789 | D24: 2 | E24: =C24*D24/O2 -> 309.41176
B26: Завтраки | C26: 8 | D26: 28 | E26: =C26*D26 -> 224
B27: Обеды | C27: 8 | D27: 28 | E27: =C27*D27 -> 224
B28: Ужины | C28: 15 | D28: 29 | E28: =C28*D28 -> 435
B29: Перекусы / вода | C29: 4 | D29: 29 | E29: =C29*D29 -> 116
B31: Обувь
B32: Палки
B33: Рюкзаки
B34: Аптечка
B35: Одежда
B38: Їжа | E38: =SUM(E26:E29) -> 999
B39: Подарки | C39: 10 | D39: 5 | E39: =C39*D39 -> 50
B40: транспорт | E40: =E6+E7+E20+E22+E23+E24 -> 454.11765
B41: підготовка | E41: =SUM(E31:E35) -> 0
B42: житло | E42: =E9+E10+E11+E12+E13+E14+E15+E16+E17+E18+E19+E21+#REF! -> #REF!

Sheet Check list
A1: 🎒 ЧЕКЛИСТ ПОДГОТОВКИ ( июль 2026)
A2: Задача | B2: Срочность | C2: Детали | D2: ☐
A3: Получить Credential (паспорт пилигрима) | B3: 🔴 ВАЖНО | C3: Купить в Sé Porto за 2€ или заказать онлайн заранее. Нужен для альберге + Compostela | D3: ☐
A4: Взять запас формулы ФКУ на 14+ дней | B4: 🔴 ВАЖНО | C4: В Португалии мало спецпродуктов — везти из Румынии. Порошок легче. | D4: ☐
A5: Забронировать жильё в Порту заранее | B5: 🔴 ВАЖНО | C5: Июль — пиковый сезон. | D5: ☐
A6: Разносить обувь (трейловые кроссовки) 2+ месяца | B6: 🟡 ВАЖНО | C6: Главная причина срыва похода — мозоли. Начать носить с мая. | D6: ☐
A7: Тренировки: ходить 15-20 км/день с рюкзаком | B7: 🟡 ФИЗПОДГОТОВКА | C7: 28 км/день в жару — проверить выносливость заранее | D7: ☐
A8: Скачать Buen Camino / Camino Ninja (бесплатно) | B8: 🟢 ПОЛЕЗНО | C8: Показывают альберге, кафе, расстояния в реальном времени | D8: ☐
A9: Рюкзак max 6-7 кг (10% от веса тела) | B9: 🟢 СНАРЯЖЕНИЕ | C9: распредилит нагрузку | D9: ☐
A10: Треккинговые палки | B10: 🟢 СНАРЯЖЕНИЕ | C10: можно в Порту купить | D10: ☐
A11: Солнцезащитный крем SPF50+, головной убор | B11: 🟢 ЗДОРОВЬЕ | C11: Июль до 35°C. Прибрежный маршрут открытый. | D11: ☐
A12: Выучить: "Um carimbo, por favor" / "Un sello, por favor" | B12: 🟢 ПРИЯТНО | C12: По-португальски и по-испански — просить печати везде! | D12: ☐

Sheet LINK
A1: https://www.caminodesantiago.gal/en/get-ready/
A2: https://oficinadelperegrino.com/en/statistics-2/
A3: https://www.gronze.com/
A4: https://play.google.com/store/apps/details?id=com.editorialbuencamino.buencamino&hl=ru
A5: https://play.google.com/store/apps/details?id=ninja.camino.app&hl=ru
A6: Maps.me
A7: Wikiloc
A8: https://www.alsa.com/en | B8: автобусный перевозчик Испании
A9: CP (Comboios de Portugal)
A10: https://rail.ninja/train/cp-train?utm_source=google&utm_medium=cpc&utm_campaign=RN_DSA_Lan_EN_Ta_EU&utm_content=735183752399&utm_term=&gad_source=1&gad_campaignid=20517683728&gbraid=0AAAAADcrsaaaioJSA4TUvMEEpB9CRYXs8&gclid=Cj0KCQiA6sjKBhCSARIsAJvYcpMick5PPTTJ-bcHCQP8zTbcdGEs-DqU4RE4mktJCDOcx_-fKJ_7w9MaAg7SEALw_wcB | B10: проехать часть пути на поезде в Португалии

Sheet кросівки
A1: https://www.alpinexpe.ro/alergare-montana/pantofi-alergare/barbati-pantofi-alergare/pantofi-alergare-trail-hoka-challenger-8-jade-truffle-salt-jdt/
A3: https://www.sportvision.ro/pantofi-sport/527116-hoka-pantofi-sport-challenger-8
A5: https://rozetka.com.ua/ua/hoka-one-one-197634704210/p474046759/
A7: https://stonefeet.ro/incaltaminte-alergare-barbati-hoka-challenger-8-maple-cardamom
